Script: Ckl_RelatorioDeRefugo
Data de execução: 2024-10-04
Hora de inicio: 22-43-09
========================================
Executando "Ckl_RelatorioDeRefugo"...
========================================

Conexão ao MySQL estabelecida com sucesso.
Traceback (most recent call last):
IDs retornados na página 1: 1000
  File "C:\Users\Usuario\AppData\Local\Packages\PythonSoftwareFoundation.Python.3.11_qbz5n2kfra8p0\LocalCache\local-packages\Python311\site-packages\urllib3\connection.py", line 203, in _new_conn
IDs já registrados no banco de dados: 17316
    sock = connection.create_connection(
Novos registros a serem registrados: 0
           ^^^^^^^^^^^^^^^^^^^^^^^^^^^^^
IDs retornados na página 2: 1000
  File "C:\Users\Usuario\AppData\Local\Packages\PythonSoftwareFoundation.Python.3.11_qbz5n2kfra8p0\LocalCache\local-packages\Python311\site-packages\urllib3\util\connection.py", line 60, in create_connection
IDs já registrados no banco de dados: 17316
    for res in socket.getaddrinfo(host, port, family, socket.SOCK_STREAM):
Novos registros a serem registrados: 0
               ^^^^^^^^^^^^^^^^^^^^^^^^^^^^^^^^^^^^^^^^^^^^^^^^^^^^^^^^^^
IDs retornados na página 3: 1000
  File "C:\Program Files\WindowsApps\PythonSoftwareFoundation.Python.3.11_3.11.2544.0_x64__qbz5n2kfra8p0\Lib\socket.py", line 962, in getaddrinfo
IDs já registrados no banco de dados: 17316
    for res in _socket.getaddrinfo(host, port, family, type, proto, flags):
Novos registros a serem registrados: 0
               ^^^^^^^^^^^^^^^^^^^^^^^^^^^^^^^^^^^^^^^^^^^^^^^^^^^^^^^^^^^
socket.gaierror: [Errno 11001] getaddrinfo failed

The above exception was the direct cause of the following exception:

Traceback (most recent call last):
  File "C:\Users\Usuario\AppData\Local\Packages\PythonSoftwareFoundation.Python.3.11_qbz5n2kfra8p0\LocalCache\local-packages\Python311\site-packages\urllib3\connectionpool.py", line 790, in urlopen
    response = self._make_request(
               ^^^^^^^^^^^^^^^^^^^
  File "C:\Users\Usuario\AppData\Local\Packages\PythonSoftwareFoundation.Python.3.11_qbz5n2kfra8p0\LocalCache\local-packages\Python311\site-packages\urllib3\connectionpool.py", line 491, in _make_request
    raise new_e
  File "C:\Users\Usuario\AppData\Local\Packages\PythonSoftwareFoundation.Python.3.11_qbz5n2kfra8p0\LocalCache\local-packages\Python311\site-packages\urllib3\connectionpool.py", line 467, in _make_request
    self._validate_conn(conn)
  File "C:\Users\Usuario\AppData\Local\Packages\PythonSoftwareFoundation.Python.3.11_qbz5n2kfra8p0\LocalCache\local-packages\Python311\site-packages\urllib3\connectionpool.py", line 1096, in _validate_conn
    conn.connect()
  File "C:\Users\Usuario\AppData\Local\Packages\PythonSoftwareFoundation.Python.3.11_qbz5n2kfra8p0\LocalCache\local-packages\Python311\site-packages\urllib3\connection.py", line 611, in connect
    self.sock = sock = self._new_conn()
                       ^^^^^^^^^^^^^^^^
  File "C:\Users\Usuario\AppData\Local\Packages\PythonSoftwareFoundation.Python.3.11_qbz5n2kfra8p0\LocalCache\local-packages\Python311\site-packages\urllib3\connection.py", line 210, in _new_conn
    raise NameResolutionError(self.host, self, e) from e
urllib3.exceptions.NameResolutionError: <urllib3.connection.HTTPSConnection object at 0x0000026036946450>: Failed to resolve 'api-analytics.checklistfacil.com.br' ([Errno 11001] getaddrinfo failed)

The above exception was the direct cause of the following exception:

Traceback (most recent call last):
  File "C:\Users\Usuario\AppData\Local\Packages\PythonSoftwareFoundation.Python.3.11_qbz5n2kfra8p0\LocalCache\local-packages\Python311\site-packages\requests\adapters.py", line 486, in send
    resp = conn.urlopen(
           ^^^^^^^^^^^^^
  File "C:\Users\Usuario\AppData\Local\Packages\PythonSoftwareFoundation.Python.3.11_qbz5n2kfra8p0\LocalCache\local-packages\Python311\site-packages\urllib3\connectionpool.py", line 844, in urlopen
    retries = retries.increment(
              ^^^^^^^^^^^^^^^^^^
  File "C:\Users\Usuario\AppData\Local\Packages\PythonSoftwareFoundation.Python.3.11_qbz5n2kfra8p0\LocalCache\local-packages\Python311\site-packages\urllib3\util\retry.py", line 515, in increment
    raise MaxRetryError(_pool, url, reason) from reason  # type: ignore[arg-type]
    ^^^^^^^^^^^^^^^^^^^^^^^^^^^^^^^^^^^^^^^^^^^^^^^^^^^
urllib3.exceptions.MaxRetryError: HTTPSConnectionPool(host='api-analytics.checklistfacil.com.br', port=443): Max retries exceeded with url: /v1/evaluations?status=6&checklistId=415456&page=4 (Caused by NameResolutionError("<urllib3.connection.HTTPSConnection object at 0x0000026036946450>: Failed to resolve 'api-analytics.checklistfacil.com.br' ([Errno 11001] getaddrinfo failed)"))

During handling of the above exception, another exception occurred:

Traceback (most recent call last):
  File "c:\Users\Usuario\OneDrive - Suzano S A\Work\1 - Codigos\Banco-GCP\Normal Scripts\Ckl_RelatorioDeRefugo.py", line 226, in <module>
    main()
  File "c:\Users\Usuario\OneDrive - Suzano S A\Work\1 - Codigos\Banco-GCP\Normal Scripts\Ckl_RelatorioDeRefugo.py", line 104, in main
    evaluation_ids = processar_pagina(url, headers)
                     ^^^^^^^^^^^^^^^^^^^^^^^^^^^^^^
  File "c:\Users\Usuario\OneDrive - Suzano S A\Work\1 - Codigos\Banco-GCP\Normal Scripts\Ckl_RelatorioDeRefugo.py", line 49, in processar_pagina
    response = requests.get(url_ConsultaIDChecklist, headers=headers, verify=False)
               ^^^^^^^^^^^^^^^^^^^^^^^^^^^^^^^^^^^^^^^^^^^^^^^^^^^^^^^^^^^^^^^^^^^^
  File "C:\Users\Usuario\AppData\Local\Packages\PythonSoftwareFoundation.Python.3.11_qbz5n2kfra8p0\LocalCache\local-packages\Python311\site-packages\requests\api.py", line 73, in get
    return request("get", url, params=params, **kwargs)
           ^^^^^^^^^^^^^^^^^^^^^^^^^^^^^^^^^^^^^^^^^^^^
  File "C:\Users\Usuario\AppData\Local\Packages\PythonSoftwareFoundation.Python.3.11_qbz5n2kfra8p0\LocalCache\local-packages\Python311\site-packages\requests\api.py", line 59, in request
    return session.request(method=method, url=url, **kwargs)
           ^^^^^^^^^^^^^^^^^^^^^^^^^^^^^^^^^^^^^^^^^^^^^^^^^
  File "C:\Users\Usuario\AppData\Local\Packages\PythonSoftwareFoundation.Python.3.11_qbz5n2kfra8p0\LocalCache\local-packages\Python311\site-packages\requests\sessions.py", line 589, in request
    resp = self.send(prep, **send_kwargs)
           ^^^^^^^^^^^^^^^^^^^^^^^^^^^^^^
  File "C:\Users\Usuario\AppData\Local\Packages\PythonSoftwareFoundation.Python.3.11_qbz5n2kfra8p0\LocalCache\local-packages\Python311\site-packages\requests\sessions.py", line 703, in send
    r = adapter.send(request, **kwargs)
        ^^^^^^^^^^^^^^^^^^^^^^^^^^^^^^^
  File "C:\Users\Usuario\AppData\Local\Packages\PythonSoftwareFoundation.Python.3.11_qbz5n2kfra8p0\LocalCache\local-packages\Python311\site-packages\requests\adapters.py", line 519, in send
    raise ConnectionError(e, request=request)
requests.exceptions.ConnectionError: HTTPSConnectionPool(host='api-analytics.checklistfacil.com.br', port=443): Max retries exceeded with url: /v1/evaluations?status=6&checklistId=415456&page=4 (Caused by NameResolutionError("<urllib3.connection.HTTPSConnection object at 0x0000026036946450>: Failed to resolve 'api-analytics.checklistfacil.com.br' ([Errno 11001] getaddrinfo failed)"))


========================================
Hora de fim: 22-47-13
========================================
