Script: CargoSnap_Proex (código antigo funcionando)
Data de execução: 2024-09-25
Hora de inicio: 14-45-46
========================================
Executando "CargoSnap_Proex (código antigo funcionando)"...
========================================

Traceback (most recent call last):
  File "C:\Users\muril\AppData\Local\Packages\PythonSoftwareFoundation.Python.3.11_qbz5n2kfra8p0\LocalCache\local-packages\Python311\site-packages\mysql\connector\network.py", line 758, in open_connection
    self.sock.connect(sockaddr)
TimeoutError: [WinError 10060] Uma tentativa de conexão falhou porque o componente conectado não respondeu

corretamente após um período de tempo ou a conexão estabelecida falhou

porque o host conectado não respondeu

The above exception was the direct cause of the following exception:

Traceback (most recent call last):
  File "c:\Users\muril\OneDrive - Suzano S A\Work\1 - Codigos\Banco-GCP\Normal Scripts\CargoSnap_Proex (código antigo funcionando).py", line 24, in <module>
    conexao = mysql.connector.connect(
              ^^^^^^^^^^^^^^^^^^^^^^^^
  File "C:\Users\muril\AppData\Local\Packages\PythonSoftwareFoundation.Python.3.11_qbz5n2kfra8p0\LocalCache\local-packages\Python311\site-packages\mysql\connector\pooling.py", line 323, in connect
    return MySQLConnection(*args, **kwargs)
           ^^^^^^^^^^^^^^^^^^^^^^^^^^^^^^^^
  File "C:\Users\muril\AppData\Local\Packages\PythonSoftwareFoundation.Python.3.11_qbz5n2kfra8p0\LocalCache\local-packages\Python311\site-packages\mysql\connector\connection.py", line 173, in __init__
    self.connect(**kwargs)
  File "C:\Users\muril\AppData\Local\Packages\PythonSoftwareFoundation.Python.3.11_qbz5n2kfra8p0\LocalCache\local-packages\Python311\site-packages\mysql\connector\abstracts.py", line 1363, in connect
    self._open_connection()
  File "C:\Users\muril\AppData\Local\Packages\PythonSoftwareFoundation.Python.3.11_qbz5n2kfra8p0\LocalCache\local-packages\Python311\site-packages\mysql\connector\connection.py", line 353, in _open_connection
    self._socket.open_connection()
  File "C:\Users\muril\AppData\Local\Packages\PythonSoftwareFoundation.Python.3.11_qbz5n2kfra8p0\LocalCache\local-packages\Python311\site-packages\mysql\connector\network.py", line 760, in open_connection
    raise InterfaceError(
mysql.connector.errors.InterfaceError: 2003: Can't connect to MySQL server on '35.224.29.30:3306' (10060 Uma tentativa de conexão falhou porque o componente conectado não respondeu

corretamente após um período de tempo ou a conexão estabelecida falhou

porque o host conectado não respondeu)


========================================
Hora de fim: 14-46-08
========================================
